<?xml version="1.0" ?>
<!-- =================================================================================== -->
<!-- |    This document was autogenerated by xacro from 4_drones.xacro                 | -->
<!-- |    EDITING THIS FILE BY HAND IS NOT RECOMMENDED                                 | -->
<!-- =================================================================================== -->
<robot name="isaac_twin">
  <link name="base_link">
    <visual>
      <geometry>
        <box size="0.01 0.01 0"/>
      </geometry>
    </visual>
  </link>
  <link name="spherical_1_x">
    <inertial>
      <mass value="0.1"/>
      <origin rpy="0 0 0" xyz="0 0 0.05"/>
      <inertia ixx="0.0001666666666666667" ixy="0" ixz="0" iyy="0.0001666666666666667" iyz="0" izz="0.0001666666666666667"/>
    </inertial>
    <visual>
      <origin rpy="0 0 0" xyz="0 0 0.05"/>
      <geometry>
        <box size="0.01 0.01 0"/>
      </geometry>
    </visual>
  </link>
  <link name="spherical_1_y">
    <inertial>
      <mass value="0.1"/>
      <origin rpy="0 0 0" xyz="0 0 0.05"/>
      <inertia ixx="0.0001666666666666667" ixy="0" ixz="0" iyy="0.0001666666666666667" iyz="0" izz="0.0001666666666666667"/>
    </inertial>
    <visual>
      <origin rpy="0 0 0" xyz="0 0 0.05"/>
      <geometry>
        <box size="0.01 0.01 0"/>
      </geometry>
    </visual>
  </link>
  <link name="spherical_1_z">
    <inertial>
      <mass value="0.1"/>
      <origin rpy="0 0 0" xyz="0 0 0.05"/>
      <inertia ixx="0.0001666666666666667" ixy="0" ixz="0" iyy="0.0001666666666666667" iyz="0" izz="0.0001666666666666667"/>
    </inertial>
    <visual>
      <origin rpy="0 0 0" xyz="0 0 0.05"/>
      <geometry>
        <box size="0.01 0.01 0"/>
      </geometry>
    </visual>
  </link>
  <joint name="spherical_1_x" type="continuous">
    <parent link="base_link"/>
    <child link="spherical_1_x"/>
    <origin rpy="0 0 0" xyz="0 0 0.0"/>
    <axis xyz="1 0 0"/>
    <!-- <limit effort="10" lower="-1.57" upper="1.57" velocity="1.0"/> -->
  </joint>
  <joint name="spherical_1_y" type="continuous">
    <parent link="spherical_1_x"/>
    <child link="spherical_1_y"/>
    <origin rpy="0 0 0" xyz="0 0 0"/>
    <axis xyz="0 1 0"/>
    <!-- <limit effort="10" lower="-1.57" upper="1.57" velocity="1.0"/> -->
  </joint>
  <joint name="spherical_1_z" type="continuous">
    <parent link="spherical_1_y"/>
    <child link="spherical_1_z"/>
    <origin rpy="0 0 0" xyz="0 0 0"/>
    <axis xyz="0 0 1"/>
  </joint>
  <joint name="prismatic_joint_1" type="prismatic">
    <parent link="spherical_1_z"/>
    <child link="Drone1"/>
    <origin rpy="0 0 0" xyz="0 0 0.05"/>
    <axis xyz="0 0 1"/>
    <limit effort="10" lower="0" upper="4" velocity="1.0"/>
  </joint>
  <link name="Drone1">
    <inertial>
      <mass value="0.1"/>
      <origin rpy="0 0 0" xyz="0 0 0"/>
      <inertia ixx="0.0008333333333333334" ixy="0" ixz="0" iyy="0.0008333333333333334" iyz="0" izz="0.0015"/>
    </inertial>
    <collision>
      <origin rpy="0 0 0" xyz="0 0 0"/>
      <geometry>
        <box size="0.3 0.3 0.3"/>
      </geometry>
    </collision>
    <visual>
      <origin rpy="0 0 0" xyz="0 0 0"/>
      <geometry>
        <box size="0.3 0.3 0.3"/>
      </geometry>
    </visual>
  </link>
  <link name="spherical_2_x">
    <inertial>
      <mass value="0.1"/>
      <origin rpy="0 0 0" xyz="0 0 0"/>
      <inertia ixx="0.0001666666666666667" ixy="0" ixz="0" iyy="0.0001666666666666667" iyz="0" izz="0.0001666666666666667"/>
    </inertial>
    <visual>
      <origin rpy="0 0 0" xyz="0 0 0"/>
      <geometry>
        <box size="0.01 0.01 0"/>
      </geometry>
    </visual>
  </link>
  <link name="spherical_2_y">
    <inertial>
      <mass value="0.1"/>
      <origin rpy="0 0 0" xyz="0 0 0"/>
      <inertia ixx="0.0001666666666666667" ixy="0" ixz="0" iyy="0.0001666666666666667" iyz="0" izz="0.0001666666666666667"/>
    </inertial>
    <visual>
      <origin rpy="0 0 0" xyz="0 0 0"/>
      <geometry>
        <box size="0.01 0.01 0"/>
      </geometry>
    </visual>
  </link>
  <link name="spherical_2_z">
    <inertial>
      <mass value="0.1"/>
      <origin rpy="0 0 0" xyz="0 0 0"/>
      <inertia ixx="0.0001666666666666667" ixy="0" ixz="0" iyy="0.0001666666666666667" iyz="0" izz="0.0001666666666666667"/>
    </inertial>
    <visual>
      <origin rpy="0 0 0" xyz="0 0 0"/>
      <geometry>
        <box size="0.01 0.01 0"/>
      </geometry>
    </visual>
  </link>
  <joint name="spherical_2_x" type="continuous">
    <parent link="Drone1"/>
    <child link="spherical_2_x"/>
    <origin rpy="0 0 0" xyz="0 0 0.0"/>
    <axis xyz="1 0 0"/>
    <!-- <limit effort="10" lower="-1.57" upper="1.57" velocity="1.0"/> -->
  </joint>
  <joint name="spherical_2_y" type="continuous">
    <parent link="spherical_2_x"/>
    <child link="spherical_2_y"/>
    <origin rpy="0 0 0" xyz="0 0 0"/>
    <axis xyz="0 1 0"/>
    <!-- <limit effort="10" lower="-1.57" upper="1.57" velocity="1.0"/> -->
  </joint>
  <joint name="spherical_2_z" type="continuous">
    <parent link="spherical_2_y"/>
    <child link="spherical_2_z"/>
    <origin rpy="0 0 0" xyz="0 0 0"/>
    <axis xyz="0 0 1"/>
  </joint>
  <joint name="prismatic_joint_2" type="prismatic">
    <parent link="spherical_2_z"/>
    <child link="Drone2"/>
    <origin rpy="0 0 0" xyz="0 0 0"/>
    <axis xyz="0 0 1"/>
    <limit effort="10" lower="0" upper="4" velocity="1.0"/>
  </joint>
  <link name="Drone2">
    <inertial>
      <mass value="0.1"/>
      <origin rpy="0 0 0" xyz="0 0 0"/>
      <inertia ixx="0.0008333333333333334" ixy="0" ixz="0" iyy="0.0008333333333333334" iyz="0" izz="0.0015"/>
    </inertial>
    <collision>
      <origin rpy="0 0 0" xyz="0 0 0"/>
      <geometry>
        <box size="0.3 0.3 0.3"/>
      </geometry>
    </collision>
    <visual>
      <origin rpy="0 0 0" xyz="0 0 0"/>
      <geometry>
        <box size="0.3 0.3 0.3"/>
      </geometry>
    </visual>
  </link>
  <link name="spherical_3_x">
    <inertial>
      <mass value="0.1"/>
      <origin rpy="0 0 0" xyz="0 0 0"/>
      <inertia ixx="0.0001666666666666667" ixy="0" ixz="0" iyy="0.0001666666666666667" iyz="0" izz="0.0001666666666666667"/>
    </inertial>
    <visual>
      <origin rpy="0 0 0" xyz="0 0 0"/>
      <geometry>
        <box size="0.01 0.01 0"/>
      </geometry>
    </visual>
  </link>
  <link name="spherical_3_y">
    <inertial>
      <mass value="0.1"/>
      <origin rpy="0 0 0" xyz="0 0 0"/>
      <inertia ixx="0.0001666666666666667" ixy="0" ixz="0" iyy="0.0001666666666666667" iyz="0" izz="0.0001666666666666667"/>
    </inertial>
    <visual>
      <origin rpy="0 0 0" xyz="0 0 0"/>
      <geometry>
        <box size="0.01 0.01 0"/>
      </geometry>
    </visual>
  </link>
  <link name="spherical_3_z">
    <inertial>
      <mass value="0.1"/>
      <origin rpy="0 0 0" xyz="0 0 0"/>
      <inertia ixx="0.0001666666666666667" ixy="0" ixz="0" iyy="0.0001666666666666667" iyz="0" izz="0.0001666666666666667"/>
    </inertial>
    <visual>
      <origin rpy="0 0 0" xyz="0 0 0"/>
      <geometry>
        <box size="0.01 0.01 0"/>
      </geometry>
    </visual>
  </link>
  <joint name="spherical_3_x" type="continuous">
    <parent link="Drone2"/>
    <child link="spherical_3_x"/>
    <origin rpy="0 0 0" xyz="0 0 0.0"/>
    <axis xyz="1 0 0"/>
    <!-- <limit effort="10" lower="-1.57" upper="1.57" velocity="1.0"/> -->
  </joint>
  <joint name="spherical_3_y" type="continuous">
    <parent link="spherical_3_x"/>
    <child link="spherical_3_y"/>
    <origin rpy="0 0 0" xyz="0 0 0"/>
    <axis xyz="0 1 0"/>
    <!-- <limit effort="10" lower="-1.57" upper="1.57" velocity="1.0"/> -->
  </joint>
  <joint name="spherical_3_z" type="continuous">
    <parent link="spherical_3_y"/>
    <child link="spherical_3_z"/>
    <origin rpy="0 0 0" xyz="0 0 0"/>
    <axis xyz="0 0 1"/>
  </joint>
  <joint name="prismatic_joint_3" type="prismatic">
    <parent link="spherical_3_z"/>
    <child link="Drone3"/>
    <origin rpy="0 0 0" xyz="0 0 0"/>
    <axis xyz="0 0 1"/>
    <limit effort="10" lower="0" upper="4" velocity="1.0"/>
  </joint>
  <link name="Drone3">
    <inertial>
      <mass value="0.1"/>
      <origin rpy="0 0 0" xyz="0 0 0"/>
      <inertia ixx="0.0008333333333333334" ixy="0" ixz="0" iyy="0.0008333333333333334" iyz="0" izz="0.0015"/>
    </inertial>
    <collision>
      <origin rpy="0 0 0" xyz="0 0 0"/>
      <geometry>
        <box size="0.3 0.3 0.3"/>
      </geometry>
    </collision>
    <visual>
      <origin rpy="0 0 0" xyz="0 0 0"/>
      <geometry>
        <box size="0.3 0.3 0.3"/>
      </geometry>
    </visual>
  </link>
  <link name="spherical_4_x">
    <inertial>
      <mass value="0.1"/>
      <origin rpy="0 0 0" xyz="0 0 0"/>
      <inertia ixx="0.0001666666666666667" ixy="0" ixz="0" iyy="0.0001666666666666667" iyz="0" izz="0.0001666666666666667"/>
    </inertial>
    <visual>
      <origin rpy="0 0 0" xyz="0 0 0"/>
      <geometry>
        <box size="0.01 0.01 0"/>
      </geometry>
    </visual>
  </link>
  <link name="spherical_4_y">
    <inertial>
      <mass value="0.1"/>
      <origin rpy="0 0 0" xyz="0 0 0"/>
      <inertia ixx="0.0001666666666666667" ixy="0" ixz="0" iyy="0.0001666666666666667" iyz="0" izz="0.0001666666666666667"/>
    </inertial>
    <visual>
      <origin rpy="0 0 0" xyz="0 0 0"/>
      <geometry>
        <box size="0.01 0.01 0"/>
      </geometry>
    </visual>
  </link>
  <link name="spherical_4_z">
    <inertial>
      <mass value="0.1"/>
      <origin rpy="0 0 0" xyz="0 0 0"/>
      <inertia ixx="0.0001666666666666667" ixy="0" ixz="0" iyy="0.0001666666666666667" iyz="0" izz="0.0001666666666666667"/>
    </inertial>
    <visual>
      <origin rpy="0 0 0" xyz="0 0 0"/>
      <geometry>
        <box size="0.01 0.01 0"/>
      </geometry>
    </visual>
  </link>
  <joint name="spherical_4_x" type="continuous">
    <parent link="Drone3"/>
    <child link="spherical_4_x"/>
    <origin rpy="0 0 0" xyz="0 0 0.0"/>
    <axis xyz="1 0 0"/>
    <!-- <limit effort="10" lower="-1.57" upper="1.57" velocity="1.0"/> -->
  </joint>
  <joint name="spherical_4_y" type="continuous">
    <parent link="spherical_4_x"/>
    <child link="spherical_4_y"/>
    <origin rpy="0 0 0" xyz="0 0 0"/>
    <axis xyz="0 1 0"/>
    <!-- <limit effort="10" lower="-1.57" upper="1.57" velocity="1.0"/> -->
  </joint>
  <joint name="spherical_4_z" type="continuous">
    <parent link="spherical_4_y"/>
    <child link="spherical_4_z"/>
    <origin rpy="0 0 0" xyz="0 0 0"/>
    <axis xyz="0 0 1"/>
  </joint>
  <joint name="prismatic_joint_4" type="prismatic">
    <parent link="spherical_4_z"/>
    <child link="Drone4"/>
    <origin rpy="0 0 0" xyz="0 0 0"/>
    <axis xyz="0 0 1"/>
    <limit effort="10" lower="0" upper="4" velocity="1.0"/>
  </joint>
  <link name="Drone4">
    <inertial>
      <mass value="0.1"/>
      <origin rpy="0 0 0" xyz="0 0 0"/>
      <inertia ixx="0.0001666666666666667" ixy="0" ixz="0" iyy="0.0001666666666666667" iyz="0" izz="0.0001666666666666667"/>
    </inertial>
    <collision>
      <origin rpy="0 0 0" xyz="0 0 0"/>
      <geometry>
        <box size="0.3 0.3 0.3"/>
      </geometry>
    </collision>
    <visual>
      <origin rpy="0 0 0" xyz="0 0 0"/>
      <geometry>
        <box size="0.3 0.3 0.3"/>
      </geometry>
    </visual>
  </link>
</robot>
