<?xml version="1.0"?>
<robot xmlns:xacro="http://www.ros.org/wiki/xacro" name="isaac_twin">



  <!-- <xacro:include filename="$(find isaac_sim_demo)/urdf/chain.xacro" /> -->
  <!-- <xacro:include filename="$(find isaac_sim_demo)/urdf/link.xacro" /> -->

<link name="base_link">
  <visual>
    <geometry>
      <box size="0.1 0.1 0"/>
    </geometry>
  </visual>
  <collision>
    <geometry>
      <box size="0.1 0.1 0"/>
    </geometry>
  </collision>
</link>


<link name="temp1">

      <visual>
        <origin rpy="0 0 0" xyz="0 0 0.00" />
        <geometry>
          <box size="0.01 0.01 0.01"/> 
        </geometry>
      </visual>
</link>

<link name="temp2">

      <visual>
        <origin rpy="0 0 0" xyz="0 0 0.00" />
        <geometry>
          <box size="0.01 0.01 0.01"/> 
        </geometry>
      </visual>
</link>

<link name="temp3">

      <visual>
        <origin rpy="0 0 0" xyz="0 0 0.00" />
        <geometry>
          <box size="0.01 0.01 0.01"/> 
        </geometry>
      </visual>
</link>

<link name="Drone1">

      <visual>
        <origin rpy="0 0 0" xyz="0 0 0.00" />
        <geometry>
          <box size="0.1 0.1 0.1"/> 
        </geometry>
      </visual>
</link>



<!-- <xacro:chain parent_link="temp3" child_link="Drone1"/>


<xacro:chain parent_link="temp7" child_link="Drone2"/>
 -->





  <joint name="joint1" type="revolute">
    <parent link="base_link"/>
    <child link="temp1"/>
    <origin xyz="0 0 0.0" rpy="0 0 0"/>
    <axis xyz="1 0 0"/>
    <limit lower="-1.57" upper="1.57" effort="10" velocity="1.0"/>
  </joint>



  <joint name="joint2" type="revolute">
    <parent link="temp1"/>
    <child link="temp2"/>
    <origin xyz="0 0 0" rpy="0 0 0"/>
    <axis xyz="0 1 0"/>
    <limit lower="-1.57" upper="1.57" effort="10" velocity="1.0"/>
  </joint>

  <joint name="joint3" type="continuous">
    <parent link="temp2"/>
    <child link="temp3"/>
    <origin xyz="0 0 0" rpy="0 0 0"/>
    <axis xyz="0 0 1"/>
    
  </joint>


  <joint name="Drone1" type="prismatic">
    <parent link="temp3"/>
    <child link="Drone1"/>
    <origin xyz="0 0 0" rpy="0 0 0"/>
    <axis xyz="0 0 1"/>
    <limit lower="0" upper="3" effort="10" velocity="1.0" />
  </joint>





<link name="temp5">
      <visual>
        <origin rpy="0 0 0" xyz="0 0 0.00" />
        <geometry>
          <box size="0.01 0.01 0.01"/> 
        </geometry>
      </visual>
</link>

<link name="temp6">

      <visual>
        <origin rpy="0 0 0" xyz="0 0 0.00" />
        <geometry>
          <box size="0.01 0.01 0.01"/> 
        </geometry>
      </visual>
</link>

<link name="temp7">
      <visual>
        <origin rpy="0 0 0" xyz="0 0 0.0" />
        <geometry>
          <box size="0.01 0.01 0.01"/> 
        </geometry>
      </visual>
</link>

<link name="Drone2">
      <visual>
        <origin rpy="0 0 0" xyz="0 0 0.0" />
        <geometry>
          <box size="0.1 0.1 0.1"/> 
        </geometry>
      </visual>
</link>


  <joint name="joint5" type="continuous">
    <parent link="Drone1"/>
    <child link="temp5"/>
    <origin xyz="0 0 0.0" rpy="0 0 0"/>
    <axis xyz="1 0 0"/>
    
  </joint>



  <joint name="joint6" type="continuous">
    <parent link="temp5"/>
    <child link="temp6"/>
    <origin xyz="0 0 0" rpy="0 0 0"/>
    <axis xyz="0 1 0"/>
    
  </joint>

  <joint name="joint7" type="continuous">
    <parent link="temp6"/>
    <child link="temp7"/>
    <origin xyz="0 0 0" rpy="0 0 0"/>
    <axis xyz="0 0 1"/>
    
  </joint>


 <joint name="drone2" type="prismatic">
    <parent link="temp7"/>
    <child link="Drone2"/>
    <origin xyz="0 0 0" rpy="0 0 0"/>
    <axis xyz="0 0 1"/>
    <limit lower="0" upper="3" effort="10" velocity="1.0" />
  </joint>




















</robot>