<?xml version="1.0" ?>
<!-- =================================================================================== -->
<!-- |    This document was autogenerated by xacro from two_drones.xacro               | -->
<!-- |    EDITING THIS FILE BY HAND IS NOT RECOMMENDED                                 | -->
<!-- =================================================================================== -->
<robot name="isaac_twin">
  <link name="base_link">
    <visual>
      <geometry>
        <box size="0.1 0.1 0"/>
      </geometry>
    </visual>
    <collision>
      <geometry>
        <box size="0.1 0.1 0"/>
      </geometry>
    </collision>
  </link>

  <joint name="floating_1" type="floating">
    <parent link="base_link"/>
    <child link="Drone1"/>
    <origin rpy="0 0 0" xyz="0 0 0.0"/>
    <axis xyz="1 0 0"/>
    <!-- <limit effort="10" lower="-1.57" upper="1.57" velocity="1.0"/> -->
  </joint>

  <link name="Drone1">
    <inertial>
      <mass value="0.1"/>
      <origin rpy="0 0 0" xyz="0 0 0"/>
      <inertia ixx="0.0001666666666666667" ixy="0" ixz="0" iyy="0.0001666666666666667" iyz="0" izz="0.0001666666666666667"/>
    </inertial>
    <collision>
      <origin rpy="0 0 0" xyz="0 0 0"/>
      <geometry>
        <box size="0.1 0.1 0.1"/>
      </geometry>
    </collision>
    <visual>
      <origin rpy="0 0 0" xyz="0 0 0"/>
      <geometry>
        <box size="0.1 0.1 0.1"/>
      </geometry>
    </visual>
  </link>

  <joint name="floating_2" type="floating">
    <parent link="Drone1"/>
    <child link="Drone2"/>
    <origin rpy="0 0 0" xyz="0 0 0.0"/>
    <axis xyz="1 0 0"/>
    <!-- <limit effort="10" lower="-1.57" upper="1.57" velocity="1.0"/> -->
  </joint>

  <link name="Drone2">
    <inertial>
      <mass value="0.1"/>
      <origin rpy="0 0 0" xyz="0 0 0"/>
      <inertia ixx="0.0001666666666666667" ixy="0" ixz="0" iyy="0.0001666666666666667" iyz="0" izz="0.0001666666666666667"/>
    </inertial>
    <collision>
      <origin rpy="0 0 0" xyz="0 0 0"/>
      <geometry>
        <box size="0.1 0.1 0.1"/>
      </geometry>
    </collision>
    <visual>
      <origin rpy="0 0 0" xyz="0 0 0"/>
      <geometry>
        <box size="0.1 0.1 0.1"/>
      </geometry>
    </visual>
  </link>
</robot>
